{
 "cells": [
  {
   "cell_type": "code",
   "execution_count": 1,
   "id": "243071b1",
   "metadata": {},
   "outputs": [],
   "source": [
    "import json\n",
    "import requests"
   ]
  },
  {
   "cell_type": "code",
   "execution_count": 2,
   "id": "39859629",
   "metadata": {},
   "outputs": [],
   "source": [
    "url = \"http://127.0.0.1:8000/havadurumu\""
   ]
  },
  {
   "cell_type": "code",
   "execution_count": 3,
   "id": "50e8ba3b",
   "metadata": {},
   "outputs": [
    {
     "ename": "ConnectionError",
     "evalue": "HTTPConnectionPool(host='127.0.0.1', port=8000): Max retries exceeded with url: /havadurumu (Caused by NewConnectionError('<urllib3.connection.HTTPConnection object at 0x0000020B4EB35CC0>: Failed to establish a new connection: [WinError 10061] Hedef makine etkin olarak reddettiğinden bağlantı kurulamadı'))",
     "output_type": "error",
     "traceback": [
      "\u001b[1;31m---------------------------------------------------------------------------\u001b[0m",
      "\u001b[1;31mConnectionRefusedError\u001b[0m                    Traceback (most recent call last)",
      "File \u001b[1;32m~\\anaconda3\\envs\\Hilal\\lib\\site-packages\\urllib3\\connection.py:174\u001b[0m, in \u001b[0;36mHTTPConnection._new_conn\u001b[1;34m(self)\u001b[0m\n\u001b[0;32m    173\u001b[0m \u001b[38;5;28;01mtry\u001b[39;00m:\n\u001b[1;32m--> 174\u001b[0m     conn \u001b[38;5;241m=\u001b[39m connection\u001b[38;5;241m.\u001b[39mcreate_connection(\n\u001b[0;32m    175\u001b[0m         (\u001b[38;5;28mself\u001b[39m\u001b[38;5;241m.\u001b[39m_dns_host, \u001b[38;5;28mself\u001b[39m\u001b[38;5;241m.\u001b[39mport), \u001b[38;5;28mself\u001b[39m\u001b[38;5;241m.\u001b[39mtimeout, \u001b[38;5;241m*\u001b[39m\u001b[38;5;241m*\u001b[39mextra_kw\n\u001b[0;32m    176\u001b[0m     )\n\u001b[0;32m    178\u001b[0m \u001b[38;5;28;01mexcept\u001b[39;00m SocketTimeout:\n",
      "File \u001b[1;32m~\\anaconda3\\envs\\Hilal\\lib\\site-packages\\urllib3\\util\\connection.py:95\u001b[0m, in \u001b[0;36mcreate_connection\u001b[1;34m(address, timeout, source_address, socket_options)\u001b[0m\n\u001b[0;32m     94\u001b[0m \u001b[38;5;28;01mif\u001b[39;00m err \u001b[38;5;129;01mis\u001b[39;00m \u001b[38;5;129;01mnot\u001b[39;00m \u001b[38;5;28;01mNone\u001b[39;00m:\n\u001b[1;32m---> 95\u001b[0m     \u001b[38;5;28;01mraise\u001b[39;00m err\n\u001b[0;32m     97\u001b[0m \u001b[38;5;28;01mraise\u001b[39;00m socket\u001b[38;5;241m.\u001b[39merror(\u001b[38;5;124m\"\u001b[39m\u001b[38;5;124mgetaddrinfo returns an empty list\u001b[39m\u001b[38;5;124m\"\u001b[39m)\n",
      "File \u001b[1;32m~\\anaconda3\\envs\\Hilal\\lib\\site-packages\\urllib3\\util\\connection.py:85\u001b[0m, in \u001b[0;36mcreate_connection\u001b[1;34m(address, timeout, source_address, socket_options)\u001b[0m\n\u001b[0;32m     84\u001b[0m     sock\u001b[38;5;241m.\u001b[39mbind(source_address)\n\u001b[1;32m---> 85\u001b[0m \u001b[43msock\u001b[49m\u001b[38;5;241;43m.\u001b[39;49m\u001b[43mconnect\u001b[49m\u001b[43m(\u001b[49m\u001b[43msa\u001b[49m\u001b[43m)\u001b[49m\n\u001b[0;32m     86\u001b[0m \u001b[38;5;28;01mreturn\u001b[39;00m sock\n",
      "\u001b[1;31mConnectionRefusedError\u001b[0m: [WinError 10061] Hedef makine etkin olarak reddettiğinden bağlantı kurulamadı",
      "\nDuring handling of the above exception, another exception occurred:\n",
      "\u001b[1;31mNewConnectionError\u001b[0m                        Traceback (most recent call last)",
      "File \u001b[1;32m~\\anaconda3\\envs\\Hilal\\lib\\site-packages\\urllib3\\connectionpool.py:714\u001b[0m, in \u001b[0;36mHTTPConnectionPool.urlopen\u001b[1;34m(self, method, url, body, headers, retries, redirect, assert_same_host, timeout, pool_timeout, release_conn, chunked, body_pos, **response_kw)\u001b[0m\n\u001b[0;32m    713\u001b[0m \u001b[38;5;66;03m# Make the request on the httplib connection object.\u001b[39;00m\n\u001b[1;32m--> 714\u001b[0m httplib_response \u001b[38;5;241m=\u001b[39m \u001b[38;5;28;43mself\u001b[39;49m\u001b[38;5;241;43m.\u001b[39;49m\u001b[43m_make_request\u001b[49m\u001b[43m(\u001b[49m\n\u001b[0;32m    715\u001b[0m \u001b[43m    \u001b[49m\u001b[43mconn\u001b[49m\u001b[43m,\u001b[49m\n\u001b[0;32m    716\u001b[0m \u001b[43m    \u001b[49m\u001b[43mmethod\u001b[49m\u001b[43m,\u001b[49m\n\u001b[0;32m    717\u001b[0m \u001b[43m    \u001b[49m\u001b[43murl\u001b[49m\u001b[43m,\u001b[49m\n\u001b[0;32m    718\u001b[0m \u001b[43m    \u001b[49m\u001b[43mtimeout\u001b[49m\u001b[38;5;241;43m=\u001b[39;49m\u001b[43mtimeout_obj\u001b[49m\u001b[43m,\u001b[49m\n\u001b[0;32m    719\u001b[0m \u001b[43m    \u001b[49m\u001b[43mbody\u001b[49m\u001b[38;5;241;43m=\u001b[39;49m\u001b[43mbody\u001b[49m\u001b[43m,\u001b[49m\n\u001b[0;32m    720\u001b[0m \u001b[43m    \u001b[49m\u001b[43mheaders\u001b[49m\u001b[38;5;241;43m=\u001b[39;49m\u001b[43mheaders\u001b[49m\u001b[43m,\u001b[49m\n\u001b[0;32m    721\u001b[0m \u001b[43m    \u001b[49m\u001b[43mchunked\u001b[49m\u001b[38;5;241;43m=\u001b[39;49m\u001b[43mchunked\u001b[49m\u001b[43m,\u001b[49m\n\u001b[0;32m    722\u001b[0m \u001b[43m\u001b[49m\u001b[43m)\u001b[49m\n\u001b[0;32m    724\u001b[0m \u001b[38;5;66;03m# If we're going to release the connection in ``finally:``, then\u001b[39;00m\n\u001b[0;32m    725\u001b[0m \u001b[38;5;66;03m# the response doesn't need to know about the connection. Otherwise\u001b[39;00m\n\u001b[0;32m    726\u001b[0m \u001b[38;5;66;03m# it will also try to release it and we'll have a double-release\u001b[39;00m\n\u001b[0;32m    727\u001b[0m \u001b[38;5;66;03m# mess.\u001b[39;00m\n",
      "File \u001b[1;32m~\\anaconda3\\envs\\Hilal\\lib\\site-packages\\urllib3\\connectionpool.py:415\u001b[0m, in \u001b[0;36mHTTPConnectionPool._make_request\u001b[1;34m(self, conn, method, url, timeout, chunked, **httplib_request_kw)\u001b[0m\n\u001b[0;32m    414\u001b[0m     \u001b[38;5;28;01melse\u001b[39;00m:\n\u001b[1;32m--> 415\u001b[0m         conn\u001b[38;5;241m.\u001b[39mrequest(method, url, \u001b[38;5;241m*\u001b[39m\u001b[38;5;241m*\u001b[39mhttplib_request_kw)\n\u001b[0;32m    417\u001b[0m \u001b[38;5;66;03m# We are swallowing BrokenPipeError (errno.EPIPE) since the server is\u001b[39;00m\n\u001b[0;32m    418\u001b[0m \u001b[38;5;66;03m# legitimately able to close the connection after sending a valid response.\u001b[39;00m\n\u001b[0;32m    419\u001b[0m \u001b[38;5;66;03m# With this behaviour, the received response is still readable.\u001b[39;00m\n",
      "File \u001b[1;32m~\\anaconda3\\envs\\Hilal\\lib\\site-packages\\urllib3\\connection.py:244\u001b[0m, in \u001b[0;36mHTTPConnection.request\u001b[1;34m(self, method, url, body, headers)\u001b[0m\n\u001b[0;32m    243\u001b[0m     headers[\u001b[38;5;124m\"\u001b[39m\u001b[38;5;124mUser-Agent\u001b[39m\u001b[38;5;124m\"\u001b[39m] \u001b[38;5;241m=\u001b[39m _get_default_user_agent()\n\u001b[1;32m--> 244\u001b[0m \u001b[38;5;28;43msuper\u001b[39;49m\u001b[43m(\u001b[49m\u001b[43mHTTPConnection\u001b[49m\u001b[43m,\u001b[49m\u001b[43m \u001b[49m\u001b[38;5;28;43mself\u001b[39;49m\u001b[43m)\u001b[49m\u001b[38;5;241;43m.\u001b[39;49m\u001b[43mrequest\u001b[49m\u001b[43m(\u001b[49m\u001b[43mmethod\u001b[49m\u001b[43m,\u001b[49m\u001b[43m \u001b[49m\u001b[43murl\u001b[49m\u001b[43m,\u001b[49m\u001b[43m \u001b[49m\u001b[43mbody\u001b[49m\u001b[38;5;241;43m=\u001b[39;49m\u001b[43mbody\u001b[49m\u001b[43m,\u001b[49m\u001b[43m \u001b[49m\u001b[43mheaders\u001b[49m\u001b[38;5;241;43m=\u001b[39;49m\u001b[43mheaders\u001b[49m\u001b[43m)\u001b[49m\n",
      "File \u001b[1;32m~\\anaconda3\\envs\\Hilal\\lib\\http\\client.py:1283\u001b[0m, in \u001b[0;36mHTTPConnection.request\u001b[1;34m(self, method, url, body, headers, encode_chunked)\u001b[0m\n\u001b[0;32m   1282\u001b[0m \u001b[38;5;250m\u001b[39m\u001b[38;5;124;03m\"\"\"Send a complete request to the server.\"\"\"\u001b[39;00m\n\u001b[1;32m-> 1283\u001b[0m \u001b[38;5;28;43mself\u001b[39;49m\u001b[38;5;241;43m.\u001b[39;49m\u001b[43m_send_request\u001b[49m\u001b[43m(\u001b[49m\u001b[43mmethod\u001b[49m\u001b[43m,\u001b[49m\u001b[43m \u001b[49m\u001b[43murl\u001b[49m\u001b[43m,\u001b[49m\u001b[43m \u001b[49m\u001b[43mbody\u001b[49m\u001b[43m,\u001b[49m\u001b[43m \u001b[49m\u001b[43mheaders\u001b[49m\u001b[43m,\u001b[49m\u001b[43m \u001b[49m\u001b[43mencode_chunked\u001b[49m\u001b[43m)\u001b[49m\n",
      "File \u001b[1;32m~\\anaconda3\\envs\\Hilal\\lib\\http\\client.py:1329\u001b[0m, in \u001b[0;36mHTTPConnection._send_request\u001b[1;34m(self, method, url, body, headers, encode_chunked)\u001b[0m\n\u001b[0;32m   1328\u001b[0m     body \u001b[38;5;241m=\u001b[39m _encode(body, \u001b[38;5;124m'\u001b[39m\u001b[38;5;124mbody\u001b[39m\u001b[38;5;124m'\u001b[39m)\n\u001b[1;32m-> 1329\u001b[0m \u001b[38;5;28;43mself\u001b[39;49m\u001b[38;5;241;43m.\u001b[39;49m\u001b[43mendheaders\u001b[49m\u001b[43m(\u001b[49m\u001b[43mbody\u001b[49m\u001b[43m,\u001b[49m\u001b[43m \u001b[49m\u001b[43mencode_chunked\u001b[49m\u001b[38;5;241;43m=\u001b[39;49m\u001b[43mencode_chunked\u001b[49m\u001b[43m)\u001b[49m\n",
      "File \u001b[1;32m~\\anaconda3\\envs\\Hilal\\lib\\http\\client.py:1278\u001b[0m, in \u001b[0;36mHTTPConnection.endheaders\u001b[1;34m(self, message_body, encode_chunked)\u001b[0m\n\u001b[0;32m   1277\u001b[0m     \u001b[38;5;28;01mraise\u001b[39;00m CannotSendHeader()\n\u001b[1;32m-> 1278\u001b[0m \u001b[38;5;28;43mself\u001b[39;49m\u001b[38;5;241;43m.\u001b[39;49m\u001b[43m_send_output\u001b[49m\u001b[43m(\u001b[49m\u001b[43mmessage_body\u001b[49m\u001b[43m,\u001b[49m\u001b[43m \u001b[49m\u001b[43mencode_chunked\u001b[49m\u001b[38;5;241;43m=\u001b[39;49m\u001b[43mencode_chunked\u001b[49m\u001b[43m)\u001b[49m\n",
      "File \u001b[1;32m~\\anaconda3\\envs\\Hilal\\lib\\http\\client.py:1038\u001b[0m, in \u001b[0;36mHTTPConnection._send_output\u001b[1;34m(self, message_body, encode_chunked)\u001b[0m\n\u001b[0;32m   1037\u001b[0m \u001b[38;5;28;01mdel\u001b[39;00m \u001b[38;5;28mself\u001b[39m\u001b[38;5;241m.\u001b[39m_buffer[:]\n\u001b[1;32m-> 1038\u001b[0m \u001b[38;5;28;43mself\u001b[39;49m\u001b[38;5;241;43m.\u001b[39;49m\u001b[43msend\u001b[49m\u001b[43m(\u001b[49m\u001b[43mmsg\u001b[49m\u001b[43m)\u001b[49m\n\u001b[0;32m   1040\u001b[0m \u001b[38;5;28;01mif\u001b[39;00m message_body \u001b[38;5;129;01mis\u001b[39;00m \u001b[38;5;129;01mnot\u001b[39;00m \u001b[38;5;28;01mNone\u001b[39;00m:\n\u001b[0;32m   1041\u001b[0m \n\u001b[0;32m   1042\u001b[0m     \u001b[38;5;66;03m# create a consistent interface to message_body\u001b[39;00m\n",
      "File \u001b[1;32m~\\anaconda3\\envs\\Hilal\\lib\\http\\client.py:976\u001b[0m, in \u001b[0;36mHTTPConnection.send\u001b[1;34m(self, data)\u001b[0m\n\u001b[0;32m    975\u001b[0m \u001b[38;5;28;01mif\u001b[39;00m \u001b[38;5;28mself\u001b[39m\u001b[38;5;241m.\u001b[39mauto_open:\n\u001b[1;32m--> 976\u001b[0m     \u001b[38;5;28;43mself\u001b[39;49m\u001b[38;5;241;43m.\u001b[39;49m\u001b[43mconnect\u001b[49m\u001b[43m(\u001b[49m\u001b[43m)\u001b[49m\n\u001b[0;32m    977\u001b[0m \u001b[38;5;28;01melse\u001b[39;00m:\n",
      "File \u001b[1;32m~\\anaconda3\\envs\\Hilal\\lib\\site-packages\\urllib3\\connection.py:205\u001b[0m, in \u001b[0;36mHTTPConnection.connect\u001b[1;34m(self)\u001b[0m\n\u001b[0;32m    204\u001b[0m \u001b[38;5;28;01mdef\u001b[39;00m \u001b[38;5;21mconnect\u001b[39m(\u001b[38;5;28mself\u001b[39m):\n\u001b[1;32m--> 205\u001b[0m     conn \u001b[38;5;241m=\u001b[39m \u001b[38;5;28;43mself\u001b[39;49m\u001b[38;5;241;43m.\u001b[39;49m\u001b[43m_new_conn\u001b[49m\u001b[43m(\u001b[49m\u001b[43m)\u001b[49m\n\u001b[0;32m    206\u001b[0m     \u001b[38;5;28mself\u001b[39m\u001b[38;5;241m.\u001b[39m_prepare_conn(conn)\n",
      "File \u001b[1;32m~\\anaconda3\\envs\\Hilal\\lib\\site-packages\\urllib3\\connection.py:186\u001b[0m, in \u001b[0;36mHTTPConnection._new_conn\u001b[1;34m(self)\u001b[0m\n\u001b[0;32m    185\u001b[0m \u001b[38;5;28;01mexcept\u001b[39;00m SocketError \u001b[38;5;28;01mas\u001b[39;00m e:\n\u001b[1;32m--> 186\u001b[0m     \u001b[38;5;28;01mraise\u001b[39;00m NewConnectionError(\n\u001b[0;32m    187\u001b[0m         \u001b[38;5;28mself\u001b[39m, \u001b[38;5;124m\"\u001b[39m\u001b[38;5;124mFailed to establish a new connection: \u001b[39m\u001b[38;5;132;01m%s\u001b[39;00m\u001b[38;5;124m\"\u001b[39m \u001b[38;5;241m%\u001b[39m e\n\u001b[0;32m    188\u001b[0m     )\n\u001b[0;32m    190\u001b[0m \u001b[38;5;28;01mreturn\u001b[39;00m conn\n",
      "\u001b[1;31mNewConnectionError\u001b[0m: <urllib3.connection.HTTPConnection object at 0x0000020B4EB35CC0>: Failed to establish a new connection: [WinError 10061] Hedef makine etkin olarak reddettiğinden bağlantı kurulamadı",
      "\nDuring handling of the above exception, another exception occurred:\n",
      "\u001b[1;31mMaxRetryError\u001b[0m                             Traceback (most recent call last)",
      "File \u001b[1;32m~\\anaconda3\\envs\\Hilal\\lib\\site-packages\\requests\\adapters.py:486\u001b[0m, in \u001b[0;36mHTTPAdapter.send\u001b[1;34m(self, request, stream, timeout, verify, cert, proxies)\u001b[0m\n\u001b[0;32m    485\u001b[0m \u001b[38;5;28;01mtry\u001b[39;00m:\n\u001b[1;32m--> 486\u001b[0m     resp \u001b[38;5;241m=\u001b[39m \u001b[43mconn\u001b[49m\u001b[38;5;241;43m.\u001b[39;49m\u001b[43murlopen\u001b[49m\u001b[43m(\u001b[49m\n\u001b[0;32m    487\u001b[0m \u001b[43m        \u001b[49m\u001b[43mmethod\u001b[49m\u001b[38;5;241;43m=\u001b[39;49m\u001b[43mrequest\u001b[49m\u001b[38;5;241;43m.\u001b[39;49m\u001b[43mmethod\u001b[49m\u001b[43m,\u001b[49m\n\u001b[0;32m    488\u001b[0m \u001b[43m        \u001b[49m\u001b[43murl\u001b[49m\u001b[38;5;241;43m=\u001b[39;49m\u001b[43murl\u001b[49m\u001b[43m,\u001b[49m\n\u001b[0;32m    489\u001b[0m \u001b[43m        \u001b[49m\u001b[43mbody\u001b[49m\u001b[38;5;241;43m=\u001b[39;49m\u001b[43mrequest\u001b[49m\u001b[38;5;241;43m.\u001b[39;49m\u001b[43mbody\u001b[49m\u001b[43m,\u001b[49m\n\u001b[0;32m    490\u001b[0m \u001b[43m        \u001b[49m\u001b[43mheaders\u001b[49m\u001b[38;5;241;43m=\u001b[39;49m\u001b[43mrequest\u001b[49m\u001b[38;5;241;43m.\u001b[39;49m\u001b[43mheaders\u001b[49m\u001b[43m,\u001b[49m\n\u001b[0;32m    491\u001b[0m \u001b[43m        \u001b[49m\u001b[43mredirect\u001b[49m\u001b[38;5;241;43m=\u001b[39;49m\u001b[38;5;28;43;01mFalse\u001b[39;49;00m\u001b[43m,\u001b[49m\n\u001b[0;32m    492\u001b[0m \u001b[43m        \u001b[49m\u001b[43massert_same_host\u001b[49m\u001b[38;5;241;43m=\u001b[39;49m\u001b[38;5;28;43;01mFalse\u001b[39;49;00m\u001b[43m,\u001b[49m\n\u001b[0;32m    493\u001b[0m \u001b[43m        \u001b[49m\u001b[43mpreload_content\u001b[49m\u001b[38;5;241;43m=\u001b[39;49m\u001b[38;5;28;43;01mFalse\u001b[39;49;00m\u001b[43m,\u001b[49m\n\u001b[0;32m    494\u001b[0m \u001b[43m        \u001b[49m\u001b[43mdecode_content\u001b[49m\u001b[38;5;241;43m=\u001b[39;49m\u001b[38;5;28;43;01mFalse\u001b[39;49;00m\u001b[43m,\u001b[49m\n\u001b[0;32m    495\u001b[0m \u001b[43m        \u001b[49m\u001b[43mretries\u001b[49m\u001b[38;5;241;43m=\u001b[39;49m\u001b[38;5;28;43mself\u001b[39;49m\u001b[38;5;241;43m.\u001b[39;49m\u001b[43mmax_retries\u001b[49m\u001b[43m,\u001b[49m\n\u001b[0;32m    496\u001b[0m \u001b[43m        \u001b[49m\u001b[43mtimeout\u001b[49m\u001b[38;5;241;43m=\u001b[39;49m\u001b[43mtimeout\u001b[49m\u001b[43m,\u001b[49m\n\u001b[0;32m    497\u001b[0m \u001b[43m        \u001b[49m\u001b[43mchunked\u001b[49m\u001b[38;5;241;43m=\u001b[39;49m\u001b[43mchunked\u001b[49m\u001b[43m,\u001b[49m\n\u001b[0;32m    498\u001b[0m \u001b[43m    \u001b[49m\u001b[43m)\u001b[49m\n\u001b[0;32m    500\u001b[0m \u001b[38;5;28;01mexcept\u001b[39;00m (ProtocolError, \u001b[38;5;167;01mOSError\u001b[39;00m) \u001b[38;5;28;01mas\u001b[39;00m err:\n",
      "File \u001b[1;32m~\\anaconda3\\envs\\Hilal\\lib\\site-packages\\urllib3\\connectionpool.py:798\u001b[0m, in \u001b[0;36mHTTPConnectionPool.urlopen\u001b[1;34m(self, method, url, body, headers, retries, redirect, assert_same_host, timeout, pool_timeout, release_conn, chunked, body_pos, **response_kw)\u001b[0m\n\u001b[0;32m    796\u001b[0m     e \u001b[38;5;241m=\u001b[39m ProtocolError(\u001b[38;5;124m\"\u001b[39m\u001b[38;5;124mConnection aborted.\u001b[39m\u001b[38;5;124m\"\u001b[39m, e)\n\u001b[1;32m--> 798\u001b[0m retries \u001b[38;5;241m=\u001b[39m \u001b[43mretries\u001b[49m\u001b[38;5;241;43m.\u001b[39;49m\u001b[43mincrement\u001b[49m\u001b[43m(\u001b[49m\n\u001b[0;32m    799\u001b[0m \u001b[43m    \u001b[49m\u001b[43mmethod\u001b[49m\u001b[43m,\u001b[49m\u001b[43m \u001b[49m\u001b[43murl\u001b[49m\u001b[43m,\u001b[49m\u001b[43m \u001b[49m\u001b[43merror\u001b[49m\u001b[38;5;241;43m=\u001b[39;49m\u001b[43me\u001b[49m\u001b[43m,\u001b[49m\u001b[43m \u001b[49m\u001b[43m_pool\u001b[49m\u001b[38;5;241;43m=\u001b[39;49m\u001b[38;5;28;43mself\u001b[39;49m\u001b[43m,\u001b[49m\u001b[43m \u001b[49m\u001b[43m_stacktrace\u001b[49m\u001b[38;5;241;43m=\u001b[39;49m\u001b[43msys\u001b[49m\u001b[38;5;241;43m.\u001b[39;49m\u001b[43mexc_info\u001b[49m\u001b[43m(\u001b[49m\u001b[43m)\u001b[49m\u001b[43m[\u001b[49m\u001b[38;5;241;43m2\u001b[39;49m\u001b[43m]\u001b[49m\n\u001b[0;32m    800\u001b[0m \u001b[43m\u001b[49m\u001b[43m)\u001b[49m\n\u001b[0;32m    801\u001b[0m retries\u001b[38;5;241m.\u001b[39msleep()\n",
      "File \u001b[1;32m~\\anaconda3\\envs\\Hilal\\lib\\site-packages\\urllib3\\util\\retry.py:592\u001b[0m, in \u001b[0;36mRetry.increment\u001b[1;34m(self, method, url, response, error, _pool, _stacktrace)\u001b[0m\n\u001b[0;32m    591\u001b[0m \u001b[38;5;28;01mif\u001b[39;00m new_retry\u001b[38;5;241m.\u001b[39mis_exhausted():\n\u001b[1;32m--> 592\u001b[0m     \u001b[38;5;28;01mraise\u001b[39;00m MaxRetryError(_pool, url, error \u001b[38;5;129;01mor\u001b[39;00m ResponseError(cause))\n\u001b[0;32m    594\u001b[0m log\u001b[38;5;241m.\u001b[39mdebug(\u001b[38;5;124m\"\u001b[39m\u001b[38;5;124mIncremented Retry for (url=\u001b[39m\u001b[38;5;124m'\u001b[39m\u001b[38;5;132;01m%s\u001b[39;00m\u001b[38;5;124m'\u001b[39m\u001b[38;5;124m): \u001b[39m\u001b[38;5;132;01m%r\u001b[39;00m\u001b[38;5;124m\"\u001b[39m, url, new_retry)\n",
      "\u001b[1;31mMaxRetryError\u001b[0m: HTTPConnectionPool(host='127.0.0.1', port=8000): Max retries exceeded with url: /havadurumu (Caused by NewConnectionError('<urllib3.connection.HTTPConnection object at 0x0000020B4EB35CC0>: Failed to establish a new connection: [WinError 10061] Hedef makine etkin olarak reddettiğinden bağlantı kurulamadı'))",
      "\nDuring handling of the above exception, another exception occurred:\n",
      "\u001b[1;31mConnectionError\u001b[0m                           Traceback (most recent call last)",
      "Cell \u001b[1;32mIn[3], line 2\u001b[0m\n\u001b[0;32m      1\u001b[0m requests_data \u001b[38;5;241m=\u001b[39m json\u001b[38;5;241m.\u001b[39mdumps({\u001b[38;5;124m\"\u001b[39m\u001b[38;5;124mhava_durumu_il\u001b[39m\u001b[38;5;124m\"\u001b[39m: \u001b[38;5;124m\"\u001b[39m\u001b[38;5;124mİstanbul\u001b[39m\u001b[38;5;124m\"\u001b[39m})\n\u001b[1;32m----> 2\u001b[0m response \u001b[38;5;241m=\u001b[39m \u001b[43mrequests\u001b[49m\u001b[38;5;241;43m.\u001b[39;49m\u001b[43mpost\u001b[49m\u001b[43m(\u001b[49m\u001b[43murl\u001b[49m\u001b[43m,\u001b[49m\u001b[43m \u001b[49m\u001b[43mrequests_data\u001b[49m\u001b[43m)\u001b[49m\n\u001b[0;32m      3\u001b[0m \u001b[38;5;28mprint\u001b[39m(response\u001b[38;5;241m.\u001b[39mtext)\n",
      "File \u001b[1;32m~\\anaconda3\\envs\\Hilal\\lib\\site-packages\\requests\\api.py:115\u001b[0m, in \u001b[0;36mpost\u001b[1;34m(url, data, json, **kwargs)\u001b[0m\n\u001b[0;32m    103\u001b[0m \u001b[38;5;28;01mdef\u001b[39;00m \u001b[38;5;21mpost\u001b[39m(url, data\u001b[38;5;241m=\u001b[39m\u001b[38;5;28;01mNone\u001b[39;00m, json\u001b[38;5;241m=\u001b[39m\u001b[38;5;28;01mNone\u001b[39;00m, \u001b[38;5;241m*\u001b[39m\u001b[38;5;241m*\u001b[39mkwargs):\n\u001b[0;32m    104\u001b[0m \u001b[38;5;250m    \u001b[39m\u001b[38;5;124mr\u001b[39m\u001b[38;5;124;03m\"\"\"Sends a POST request.\u001b[39;00m\n\u001b[0;32m    105\u001b[0m \n\u001b[0;32m    106\u001b[0m \u001b[38;5;124;03m    :param url: URL for the new :class:`Request` object.\u001b[39;00m\n\u001b[1;32m   (...)\u001b[0m\n\u001b[0;32m    112\u001b[0m \u001b[38;5;124;03m    :rtype: requests.Response\u001b[39;00m\n\u001b[0;32m    113\u001b[0m \u001b[38;5;124;03m    \"\"\"\u001b[39;00m\n\u001b[1;32m--> 115\u001b[0m     \u001b[38;5;28;01mreturn\u001b[39;00m request(\u001b[38;5;124m\"\u001b[39m\u001b[38;5;124mpost\u001b[39m\u001b[38;5;124m\"\u001b[39m, url, data\u001b[38;5;241m=\u001b[39mdata, json\u001b[38;5;241m=\u001b[39mjson, \u001b[38;5;241m*\u001b[39m\u001b[38;5;241m*\u001b[39mkwargs)\n",
      "File \u001b[1;32m~\\anaconda3\\envs\\Hilal\\lib\\site-packages\\requests\\api.py:59\u001b[0m, in \u001b[0;36mrequest\u001b[1;34m(method, url, **kwargs)\u001b[0m\n\u001b[0;32m     55\u001b[0m \u001b[38;5;66;03m# By using the 'with' statement we are sure the session is closed, thus we\u001b[39;00m\n\u001b[0;32m     56\u001b[0m \u001b[38;5;66;03m# avoid leaving sockets open which can trigger a ResourceWarning in some\u001b[39;00m\n\u001b[0;32m     57\u001b[0m \u001b[38;5;66;03m# cases, and look like a memory leak in others.\u001b[39;00m\n\u001b[0;32m     58\u001b[0m \u001b[38;5;28;01mwith\u001b[39;00m sessions\u001b[38;5;241m.\u001b[39mSession() \u001b[38;5;28;01mas\u001b[39;00m session:\n\u001b[1;32m---> 59\u001b[0m     \u001b[38;5;28;01mreturn\u001b[39;00m session\u001b[38;5;241m.\u001b[39mrequest(method\u001b[38;5;241m=\u001b[39mmethod, url\u001b[38;5;241m=\u001b[39murl, \u001b[38;5;241m*\u001b[39m\u001b[38;5;241m*\u001b[39mkwargs)\n",
      "File \u001b[1;32m~\\anaconda3\\envs\\Hilal\\lib\\site-packages\\requests\\sessions.py:589\u001b[0m, in \u001b[0;36mSession.request\u001b[1;34m(self, method, url, params, data, headers, cookies, files, auth, timeout, allow_redirects, proxies, hooks, stream, verify, cert, json)\u001b[0m\n\u001b[0;32m    584\u001b[0m send_kwargs \u001b[38;5;241m=\u001b[39m {\n\u001b[0;32m    585\u001b[0m     \u001b[38;5;124m\"\u001b[39m\u001b[38;5;124mtimeout\u001b[39m\u001b[38;5;124m\"\u001b[39m: timeout,\n\u001b[0;32m    586\u001b[0m     \u001b[38;5;124m\"\u001b[39m\u001b[38;5;124mallow_redirects\u001b[39m\u001b[38;5;124m\"\u001b[39m: allow_redirects,\n\u001b[0;32m    587\u001b[0m }\n\u001b[0;32m    588\u001b[0m send_kwargs\u001b[38;5;241m.\u001b[39mupdate(settings)\n\u001b[1;32m--> 589\u001b[0m resp \u001b[38;5;241m=\u001b[39m \u001b[38;5;28mself\u001b[39m\u001b[38;5;241m.\u001b[39msend(prep, \u001b[38;5;241m*\u001b[39m\u001b[38;5;241m*\u001b[39msend_kwargs)\n\u001b[0;32m    591\u001b[0m \u001b[38;5;28;01mreturn\u001b[39;00m resp\n",
      "File \u001b[1;32m~\\anaconda3\\envs\\Hilal\\lib\\site-packages\\requests\\sessions.py:703\u001b[0m, in \u001b[0;36mSession.send\u001b[1;34m(self, request, **kwargs)\u001b[0m\n\u001b[0;32m    700\u001b[0m start \u001b[38;5;241m=\u001b[39m preferred_clock()\n\u001b[0;32m    702\u001b[0m \u001b[38;5;66;03m# Send the request\u001b[39;00m\n\u001b[1;32m--> 703\u001b[0m r \u001b[38;5;241m=\u001b[39m adapter\u001b[38;5;241m.\u001b[39msend(request, \u001b[38;5;241m*\u001b[39m\u001b[38;5;241m*\u001b[39mkwargs)\n\u001b[0;32m    705\u001b[0m \u001b[38;5;66;03m# Total elapsed time of the request (approximately)\u001b[39;00m\n\u001b[0;32m    706\u001b[0m elapsed \u001b[38;5;241m=\u001b[39m preferred_clock() \u001b[38;5;241m-\u001b[39m start\n",
      "File \u001b[1;32m~\\anaconda3\\envs\\Hilal\\lib\\site-packages\\requests\\adapters.py:519\u001b[0m, in \u001b[0;36mHTTPAdapter.send\u001b[1;34m(self, request, stream, timeout, verify, cert, proxies)\u001b[0m\n\u001b[0;32m    515\u001b[0m     \u001b[38;5;28;01mif\u001b[39;00m \u001b[38;5;28misinstance\u001b[39m(e\u001b[38;5;241m.\u001b[39mreason, _SSLError):\n\u001b[0;32m    516\u001b[0m         \u001b[38;5;66;03m# This branch is for urllib3 v1.22 and later.\u001b[39;00m\n\u001b[0;32m    517\u001b[0m         \u001b[38;5;28;01mraise\u001b[39;00m SSLError(e, request\u001b[38;5;241m=\u001b[39mrequest)\n\u001b[1;32m--> 519\u001b[0m     \u001b[38;5;28;01mraise\u001b[39;00m \u001b[38;5;167;01mConnectionError\u001b[39;00m(e, request\u001b[38;5;241m=\u001b[39mrequest)\n\u001b[0;32m    521\u001b[0m \u001b[38;5;28;01mexcept\u001b[39;00m ClosedPoolError \u001b[38;5;28;01mas\u001b[39;00m e:\n\u001b[0;32m    522\u001b[0m     \u001b[38;5;28;01mraise\u001b[39;00m \u001b[38;5;167;01mConnectionError\u001b[39;00m(e, request\u001b[38;5;241m=\u001b[39mrequest)\n",
      "\u001b[1;31mConnectionError\u001b[0m: HTTPConnectionPool(host='127.0.0.1', port=8000): Max retries exceeded with url: /havadurumu (Caused by NewConnectionError('<urllib3.connection.HTTPConnection object at 0x0000020B4EB35CC0>: Failed to establish a new connection: [WinError 10061] Hedef makine etkin olarak reddettiğinden bağlantı kurulamadı'))"
     ]
    }
   ],
   "source": [
    "requests_data = json.dumps({\"hava_durumu_il\": \"İstanbul\"})\n",
    "response = requests.post(url, requests_data)\n",
    "print(response.text)"
   ]
  },
  {
   "cell_type": "code",
   "execution_count": null,
   "id": "a60dcfd9",
   "metadata": {},
   "outputs": [],
   "source": []
  }
 ],
 "metadata": {
  "kernelspec": {
   "display_name": "Python 3 (ipykernel)",
   "language": "python",
   "name": "python3"
  },
  "language_info": {
   "codemirror_mode": {
    "name": "ipython",
    "version": 3
   },
   "file_extension": ".py",
   "mimetype": "text/x-python",
   "name": "python",
   "nbconvert_exporter": "python",
   "pygments_lexer": "ipython3",
   "version": "3.10.13"
  }
 },
 "nbformat": 4,
 "nbformat_minor": 5
}
